<?xml version="1.0" encoding="utf-8" standalone="no"?>
<test-run id="2" testcasecount="13" result="Failed" total="13" passed="0" failed="13" inconclusive="0" skipped="0" asserts="0" engine-version="3.4.1.0" clr-version="4.0.30319.42000" start-time="2016-09-07 09:51:19Z" end-time="2016-09-07 09:51:19Z" duration="0.209323">
  <command-line><![CDATA[/home/wessel/var/doc/ingenico_api/projects/csharp/connect-sdk-dotnet/packages/NUnit.ConsoleRunner.3.4.1/tools/nunit3-console.exe bin/Debug/connect-sdk-dotnet-it.dll]]></command-line>
  <test-suite type="Assembly" id="0-1034" name="connect-sdk-dotnet-it.dll" fullname="/home/wessel/var/doc/ingenico_api/projects/csharp/connect-sdk-dotnet/connect-sdk-dotnet-it/bin/Debug/connect-sdk-dotnet-it.dll" runstate="Runnable" testcasecount="13" result="Failed" site="Child" start-time="2016-09-07 09:51:19Z" end-time="2016-09-07 09:51:19Z" duration="0.124868" total="13" passed="0" failed="13" inconclusive="0" skipped="0" asserts="0">
    <environment framework-version="3.4.1.0" clr-version="4.0.30319.42000" os-version="Unix 4.7.2.1" platform="Unix" cwd="/home/wessel/var/doc/ingenico_api/projects/csharp/connect-sdk-dotnet/connect-sdk-dotnet-it" machine-name="Wessel-Arch" user="wessel" user-domain="Wessel-Arch" culture="en-US" uiculture="en-US" os-architecture="x64" />
    <settings>
      <setting name="WorkDirectory" value="/home/wessel/var/doc/ingenico_api/projects/csharp/connect-sdk-dotnet/connect-sdk-dotnet-it" />
      <setting name="ImageRuntimeVersion" value="4.0.30319" />
      <setting name="ImageRequiresX86" value="False" />
      <setting name="ImageRequiresDefaultAppDomainAssemblyResolver" value="False" />
      <setting name="NumberOfTestWorkers" value="8" />
    </settings>
    <properties>
      <property name="_PID" value="29546" />
      <property name="_APPDOMAIN" value="test-domain-" />
    </properties>
    <failure>
      <message><![CDATA[One or more child tests had errors]]></message>
    </failure>
    <test-suite type="TestSuite" id="0-1035" name="Ingenico" fullname="Ingenico" runstate="Runnable" testcasecount="13" result="Failed" site="Child" start-time="2016-09-07 09:51:19Z" end-time="2016-09-07 09:51:19Z" duration="0.115493" total="13" passed="0" failed="13" inconclusive="0" skipped="0" asserts="0">
      <failure>
        <message><![CDATA[One or more child tests had errors]]></message>
      </failure>
      <test-suite type="TestSuite" id="0-1036" name="Connect" fullname="Ingenico.Connect" runstate="Runnable" testcasecount="13" result="Failed" site="Child" start-time="2016-09-07 09:51:19Z" end-time="2016-09-07 09:51:19Z" duration="0.113287" total="13" passed="0" failed="13" inconclusive="0" skipped="0" asserts="0">
        <failure>
          <message><![CDATA[One or more child tests had errors]]></message>
        </failure>
        <test-suite type="TestSuite" id="0-1037" name="Sdk" fullname="Ingenico.Connect.Sdk" runstate="Runnable" testcasecount="13" result="Failed" site="Child" start-time="2016-09-07 09:51:19Z" end-time="2016-09-07 09:51:19Z" duration="0.111202" total="13" passed="0" failed="13" inconclusive="0" skipped="0" asserts="0">
          <failure>
            <message><![CDATA[One or more child tests had errors]]></message>
          </failure>
          <test-suite type="TestSuite" id="0-1038" name="It" fullname="Ingenico.Connect.Sdk.It" runstate="Runnable" testcasecount="13" result="Failed" site="Child" start-time="2016-09-07 09:51:19Z" end-time="2016-09-07 09:51:19Z" duration="0.109083" total="13" passed="0" failed="13" inconclusive="0" skipped="0" asserts="0">
            <failure>
              <message><![CDATA[One or more child tests had errors]]></message>
            </failure>
            <test-suite type="TestFixture" id="0-1000" name="ConnectionPoolingTest" fullname="Ingenico.Connect.Sdk.It.ConnectionPoolingTest" classname="Ingenico.Connect.Sdk.It.ConnectionPoolingTest" runstate="Runnable" testcasecount="3" result="Failed" site="Child" start-time="2016-09-07 09:51:19Z" end-time="2016-09-07 09:51:19Z" duration="0.029939" total="3" passed="0" failed="3" inconclusive="0" skipped="0" asserts="0">
              <failure>
                <message><![CDATA[One or more child tests had errors]]></message>
              </failure>
              <test-suite type="ParameterizedMethod" id="0-1004" name="TestconnectionPooling" fullname="Ingenico.Connect.Sdk.It.ConnectionPoolingTest.TestconnectionPooling" classname="Ingenico.Connect.Sdk.It.ConnectionPoolingTest" runstate="Runnable" testcasecount="3" result="Failed" site="Child" start-time="2016-09-07 09:51:19Z" end-time="2016-09-07 09:51:19Z" duration="0.026369" total="3" passed="0" failed="3" inconclusive="0" skipped="0" asserts="0">
                <failure>
                  <message><![CDATA[One or more child tests had errors]]></message>
                </failure>
                <test-case id="0-1001" name="TestconnectionPooling(10,10)" fullname="Ingenico.Connect.Sdk.It.ConnectionPoolingTest.TestconnectionPooling(10,10)" methodname="TestconnectionPooling" classname="Ingenico.Connect.Sdk.It.ConnectionPoolingTest" runstate="Runnable" seed="972487184" result="Failed" label="Error" start-time="2016-09-07 09:51:19Z" end-time="2016-09-07 09:51:19Z" duration="0.015084" asserts="0">
                  <failure>
                    <message><![CDATA[System.InvalidOperationException : Environment variables connect.api.apiKeyId and connect.api.secretApiKey must be set]]></message>
                    <stack-trace><![CDATA[  at Ingenico.Connect.Sdk.It.IntegrationTest.GetCommunicatorConfiguration () <0x420a8fa0 + 0x00063> in <filename unknown>:0 
  at Ingenico.Connect.Sdk.It.ConnectionPoolingTest+<TestconnectionPooling>c__async0.MoveNext () <0x420a8b50 + 0x00077> in <filename unknown>:0 
--- End of stack trace from previous location where exception was thrown ---
  at System.Runtime.ExceptionServices.ExceptionDispatchInfo.Throw () <0x420af8e0 + 0x00033> in <filename unknown>:0 
  at NUnit.Framework.Internal.ExceptionHelper.Rethrow (System.Exception exception) <0x420af8b0 + 0x00027> in <filename unknown>:0 
  at NUnit.Framework.Internal.AsyncInvocationRegion+AsyncTaskInvocationRegion.WaitForPendingOperationsToComplete (System.Object invocationResult) <0x420ac080 + 0x000c3> in <filename unknown>:0 
  at NUnit.Framework.Internal.Commands.TestMethodCommand.RunAsyncTestMethod (NUnit.Framework.Internal.TestExecutionContext context) <0x420a7670 + 0x000b0> in <filename unknown>:0 ]]></stack-trace>
                  </failure>
                </test-case>
                <test-case id="0-1002" name="TestconnectionPooling(10,5)" fullname="Ingenico.Connect.Sdk.It.ConnectionPoolingTest.TestconnectionPooling(10,5)" methodname="TestconnectionPooling" classname="Ingenico.Connect.Sdk.It.ConnectionPoolingTest" runstate="Runnable" seed="108467787" result="Failed" label="Error" start-time="2016-09-07 09:51:19Z" end-time="2016-09-07 09:51:19Z" duration="0.000155" asserts="0">
                  <failure>
                    <message><![CDATA[System.InvalidOperationException : Environment variables connect.api.apiKeyId and connect.api.secretApiKey must be set]]></message>
                    <stack-trace><![CDATA[  at Ingenico.Connect.Sdk.It.IntegrationTest.GetCommunicatorConfiguration () <0x420a8fa0 + 0x00063> in <filename unknown>:0 
  at Ingenico.Connect.Sdk.It.ConnectionPoolingTest+<TestconnectionPooling>c__async0.MoveNext () <0x420a8b50 + 0x00077> in <filename unknown>:0 
--- End of stack trace from previous location where exception was thrown ---
  at System.Runtime.ExceptionServices.ExceptionDispatchInfo.Throw () <0x420af8e0 + 0x00033> in <filename unknown>:0 
  at NUnit.Framework.Internal.ExceptionHelper.Rethrow (System.Exception exception) <0x420af8b0 + 0x00027> in <filename unknown>:0 
  at NUnit.Framework.Internal.AsyncInvocationRegion+AsyncTaskInvocationRegion.WaitForPendingOperationsToComplete (System.Object invocationResult) <0x420ac080 + 0x000c3> in <filename unknown>:0 
  at NUnit.Framework.Internal.Commands.TestMethodCommand.RunAsyncTestMethod (NUnit.Framework.Internal.TestExecutionContext context) <0x420a7670 + 0x000b0> in <filename unknown>:0 ]]></stack-trace>
                  </failure>
                </test-case>
                <test-case id="0-1003" name="TestconnectionPooling(10,1)" fullname="Ingenico.Connect.Sdk.It.ConnectionPoolingTest.TestconnectionPooling(10,1)" methodname="TestconnectionPooling" classname="Ingenico.Connect.Sdk.It.ConnectionPoolingTest" runstate="Runnable" seed="2052863971" result="Failed" label="Error" start-time="2016-09-07 09:51:19Z" end-time="2016-09-07 09:51:19Z" duration="0.000127" asserts="0">
                  <failure>
                    <message><![CDATA[System.InvalidOperationException : Environment variables connect.api.apiKeyId and connect.api.secretApiKey must be set]]></message>
                    <stack-trace><![CDATA[  at Ingenico.Connect.Sdk.It.IntegrationTest.GetCommunicatorConfiguration () <0x420a8fa0 + 0x00063> in <filename unknown>:0 
  at Ingenico.Connect.Sdk.It.ConnectionPoolingTest+<TestconnectionPooling>c__async0.MoveNext () <0x420a8b50 + 0x00077> in <filename unknown>:0 
--- End of stack trace from previous location where exception was thrown ---
  at System.Runtime.ExceptionServices.ExceptionDispatchInfo.Throw () <0x420af8e0 + 0x00033> in <filename unknown>:0 
  at NUnit.Framework.Internal.ExceptionHelper.Rethrow (System.Exception exception) <0x420af8b0 + 0x00027> in <filename unknown>:0 
  at NUnit.Framework.Internal.AsyncInvocationRegion+AsyncTaskInvocationRegion.WaitForPendingOperationsToComplete (System.Object invocationResult) <0x420ac080 + 0x000c3> in <filename unknown>:0 
  at NUnit.Framework.Internal.Commands.TestMethodCommand.RunAsyncTestMethod (NUnit.Framework.Internal.TestExecutionContext context) <0x420a7670 + 0x000b0> in <filename unknown>:0 ]]></stack-trace>
                  </failure>
                </test-case>
              </test-suite>
            </test-suite>
            <test-suite type="TestFixture" id="0-1031" name="ConnectionTestTest" fullname="Ingenico.Connect.Sdk.It.ConnectionTestTest" classname="Ingenico.Connect.Sdk.It.ConnectionTestTest" runstate="Runnable" testcasecount="1" result="Failed" site="Child" start-time="2016-09-07 09:51:19Z" end-time="2016-09-07 09:51:19Z" duration="0.005350" total="1" passed="0" failed="1" inconclusive="0" skipped="0" asserts="0">
              <failure>
                <message><![CDATA[One or more child tests had errors]]></message>
              </failure>
              <test-suite type="ParameterizedMethod" id="0-1033" name="Test" fullname="Ingenico.Connect.Sdk.It.ConnectionTestTest.Test" classname="Ingenico.Connect.Sdk.It.ConnectionTestTest" runstate="Runnable" testcasecount="1" result="Failed" site="Child" start-time="2016-09-07 09:51:19Z" end-time="2016-09-07 09:51:19Z" duration="0.003099" total="1" passed="0" failed="1" inconclusive="0" skipped="0" asserts="0">
                <failure>
                  <message><![CDATA[One or more child tests had errors]]></message>
                </failure>
                <test-case id="0-1032" name="Test()" fullname="Ingenico.Connect.Sdk.It.ConnectionTestTest.Test()" methodname="Test" classname="Ingenico.Connect.Sdk.It.ConnectionTestTest" runstate="Runnable" seed="61795805" result="Failed" label="Error" start-time="2016-09-07 09:51:19Z" end-time="2016-09-07 09:51:19Z" duration="0.000899" asserts="0">
                  <failure>
                    <message><![CDATA[System.InvalidOperationException : Environment variables connect.api.apiKeyId and connect.api.secretApiKey must be set]]></message>
                    <stack-trace><![CDATA[  at Ingenico.Connect.Sdk.It.IntegrationTest.GetClient () <0x420c0cd0 + 0x0007f> in <filename unknown>:0 
  at Ingenico.Connect.Sdk.It.ConnectionTestTest+<Test>c__async0.MoveNext () <0x420c0940 + 0x00073> in <filename unknown>:0 
--- End of stack trace from previous location where exception was thrown ---
  at System.Runtime.ExceptionServices.ExceptionDispatchInfo.Throw () <0x420af8e0 + 0x00033> in <filename unknown>:0 
  at NUnit.Framework.Internal.ExceptionHelper.Rethrow (System.Exception exception) <0x420af8b0 + 0x00027> in <filename unknown>:0 
  at NUnit.Framework.Internal.AsyncInvocationRegion+AsyncTaskInvocationRegion.WaitForPendingOperationsToComplete (System.Object invocationResult) <0x420ac080 + 0x000c3> in <filename unknown>:0 
  at NUnit.Framework.Internal.Commands.TestMethodCommand.RunAsyncTestMethod (NUnit.Framework.Internal.TestExecutionContext context) <0x420a7670 + 0x000b0> in <filename unknown>:0 ]]></stack-trace>
                  </failure>
                </test-case>
              </test-suite>
            </test-suite>
            <test-suite type="TestFixture" id="0-1005" name="ConvertAmountTest" fullname="Ingenico.Connect.Sdk.It.ConvertAmountTest" classname="Ingenico.Connect.Sdk.It.ConvertAmountTest" runstate="Runnable" testcasecount="1" result="Failed" site="Child" start-time="2016-09-07 09:51:19Z" end-time="2016-09-07 09:51:19Z" duration="0.005433" total="1" passed="0" failed="1" inconclusive="0" skipped="0" asserts="0">
              <failure>
                <message><![CDATA[One or more child tests had errors]]></message>
              </failure>
              <test-suite type="ParameterizedMethod" id="0-1007" name="Test" fullname="Ingenico.Connect.Sdk.It.ConvertAmountTest.Test" classname="Ingenico.Connect.Sdk.It.ConvertAmountTest" runstate="Runnable" testcasecount="1" result="Failed" site="Child" start-time="2016-09-07 09:51:19Z" end-time="2016-09-07 09:51:19Z" duration="0.003143" total="1" passed="0" failed="1" inconclusive="0" skipped="0" asserts="0">
                <failure>
                  <message><![CDATA[One or more child tests had errors]]></message>
                </failure>
                <test-case id="0-1006" name="Test()" fullname="Ingenico.Connect.Sdk.It.ConvertAmountTest.Test()" methodname="Test" classname="Ingenico.Connect.Sdk.It.ConvertAmountTest" runstate="Runnable" seed="1896298453" result="Failed" label="Error" start-time="2016-09-07 09:51:19Z" end-time="2016-09-07 09:51:19Z" duration="0.000913" asserts="0">
                  <failure>
                    <message><![CDATA[System.InvalidOperationException : Environment variables connect.api.apiKeyId and connect.api.secretApiKey must be set]]></message>
                    <stack-trace><![CDATA[  at Ingenico.Connect.Sdk.It.IntegrationTest.GetClient () <0x420c0cd0 + 0x0007f> in <filename unknown>:0 
  at Ingenico.Connect.Sdk.It.ConvertAmountTest+<Test>c__async0.MoveNext () <0x420c1060 + 0x001ff> in <filename unknown>:0 
--- End of stack trace from previous location where exception was thrown ---
  at System.Runtime.ExceptionServices.ExceptionDispatchInfo.Throw () <0x420af8e0 + 0x00033> in <filename unknown>:0 
  at NUnit.Framework.Internal.ExceptionHelper.Rethrow (System.Exception exception) <0x420af8b0 + 0x00027> in <filename unknown>:0 
  at NUnit.Framework.Internal.AsyncInvocationRegion+AsyncTaskInvocationRegion.WaitForPendingOperationsToComplete (System.Object invocationResult) <0x420ac080 + 0x000c3> in <filename unknown>:0 
  at NUnit.Framework.Internal.Commands.TestMethodCommand.RunAsyncTestMethod (NUnit.Framework.Internal.TestExecutionContext context) <0x420a7670 + 0x000b0> in <filename unknown>:0 ]]></stack-trace>
                  </failure>
                </test-case>
              </test-suite>
            </test-suite>
            <test-suite type="TestFixture" id="0-1008" name="IdemPotenceTest" fullname="Ingenico.Connect.Sdk.It.IdemPotenceTest" classname="Ingenico.Connect.Sdk.It.IdemPotenceTest" runstate="Runnable" testcasecount="1" result="Failed" site="Child" start-time="2016-09-07 09:51:19Z" end-time="2016-09-07 09:51:19Z" duration="0.006507" total="1" passed="0" failed="1" inconclusive="0" skipped="0" asserts="0">
              <failure>
                <message><![CDATA[One or more child tests had errors]]></message>
              </failure>
              <test-suite type="ParameterizedMethod" id="0-1010" name="Test" fullname="Ingenico.Connect.Sdk.It.IdemPotenceTest.Test" classname="Ingenico.Connect.Sdk.It.IdemPotenceTest" runstate="Runnable" testcasecount="1" result="Failed" site="Child" start-time="2016-09-07 09:51:19Z" end-time="2016-09-07 09:51:19Z" duration="0.004113" total="1" passed="0" failed="1" inconclusive="0" skipped="0" asserts="0">
                <failure>
                  <message><![CDATA[One or more child tests had errors]]></message>
                </failure>
                <test-case id="0-1009" name="Test()" fullname="Ingenico.Connect.Sdk.It.IdemPotenceTest.Test()" methodname="Test" classname="Ingenico.Connect.Sdk.It.IdemPotenceTest" runstate="Runnable" seed="1695193619" result="Failed" label="Error" start-time="2016-09-07 09:51:19Z" end-time="2016-09-07 09:51:19Z" duration="0.001868" asserts="0">
                  <failure>
                    <message><![CDATA[System.InvalidOperationException : Environment variables connect.api.apiKeyId and connect.api.secretApiKey must be set]]></message>
                    <stack-trace><![CDATA[  at Ingenico.Connect.Sdk.It.IntegrationTest.GetClient () <0x420c0cd0 + 0x0007f> in <filename unknown>:0 
  at Ingenico.Connect.Sdk.It.IdemPotenceTest+<Test>c__async0.MoveNext () <0x420c1a00 + 0x009c7> in <filename unknown>:0 
--- End of stack trace from previous location where exception was thrown ---
  at System.Runtime.ExceptionServices.ExceptionDispatchInfo.Throw () <0x420af8e0 + 0x00033> in <filename unknown>:0 
  at NUnit.Framework.Internal.ExceptionHelper.Rethrow (System.Exception exception) <0x420af8b0 + 0x00027> in <filename unknown>:0 
  at NUnit.Framework.Internal.AsyncInvocationRegion+AsyncTaskInvocationRegion.WaitForPendingOperationsToComplete (System.Object invocationResult) <0x420ac080 + 0x000c3> in <filename unknown>:0 
  at NUnit.Framework.Internal.Commands.TestMethodCommand.RunAsyncTestMethod (NUnit.Framework.Internal.TestExecutionContext context) <0x420a7670 + 0x000b0> in <filename unknown>:0 ]]></stack-trace>
                  </failure>
                </test-case>
              </test-suite>
            </test-suite>
            <test-suite type="TestFixture" id="0-1011" name="MultiLineHeaderTest" fullname="Ingenico.Connect.Sdk.It.MultiLineHeaderTest" classname="Ingenico.Connect.Sdk.It.MultiLineHeaderTest" runstate="Runnable" testcasecount="2" result="Failed" site="Child" start-time="2016-09-07 09:51:19Z" end-time="2016-09-07 09:51:19Z" duration="0.012747" total="2" passed="0" failed="2" inconclusive="0" skipped="0" asserts="0">
              <failure>
                <message><![CDATA[One or more child tests had errors]]></message>
              </failure>
              <test-suite type="ParameterizedMethod" id="0-1015" name="SimpleTest" fullname="Ingenico.Connect.Sdk.It.MultiLineHeaderTest.SimpleTest" classname="Ingenico.Connect.Sdk.It.MultiLineHeaderTest" runstate="Runnable" testcasecount="1" result="Failed" site="Child" start-time="2016-09-07 09:51:19Z" end-time="2016-09-07 09:51:19Z" duration="0.003093" total="1" passed="0" failed="1" inconclusive="0" skipped="0" asserts="0">
                <failure>
                  <message><![CDATA[One or more child tests had errors]]></message>
                </failure>
                <test-case id="0-1014" name="SimpleTest()" fullname="Ingenico.Connect.Sdk.It.MultiLineHeaderTest.SimpleTest()" methodname="SimpleTest" classname="Ingenico.Connect.Sdk.It.MultiLineHeaderTest" runstate="Runnable" seed="2122456283" result="Failed" label="Error" start-time="2016-09-07 09:51:19Z" end-time="2016-09-07 09:51:19Z" duration="0.000884" asserts="0">
                  <failure>
                    <message><![CDATA[System.InvalidOperationException : Environment variables connect.api.apiKeyId and connect.api.secretApiKey must be set]]></message>
                    <stack-trace><![CDATA[  at Ingenico.Connect.Sdk.It.IntegrationTest.GetCommunicatorConfiguration () <0x420a8fa0 + 0x00063> in <filename unknown>:0 
  at Ingenico.Connect.Sdk.It.MultiLineHeaderTest+<SimpleTest>c__async1.MoveNext () <0x420c35a0 + 0x00083> in <filename unknown>:0 
--- End of stack trace from previous location where exception was thrown ---
  at System.Runtime.ExceptionServices.ExceptionDispatchInfo.Throw () <0x420af8e0 + 0x00033> in <filename unknown>:0 
  at NUnit.Framework.Internal.ExceptionHelper.Rethrow (System.Exception exception) <0x420af8b0 + 0x00027> in <filename unknown>:0 
  at NUnit.Framework.Internal.AsyncInvocationRegion+AsyncTaskInvocationRegion.WaitForPendingOperationsToComplete (System.Object invocationResult) <0x420ac080 + 0x000c3> in <filename unknown>:0 
  at NUnit.Framework.Internal.Commands.TestMethodCommand.RunAsyncTestMethod (NUnit.Framework.Internal.TestExecutionContext context) <0x420a7670 + 0x000b0> in <filename unknown>:0 ]]></stack-trace>
                  </failure>
                </test-case>
              </test-suite>
              <test-suite type="ParameterizedMethod" id="0-1013" name="Test" fullname="Ingenico.Connect.Sdk.It.MultiLineHeaderTest.Test" classname="Ingenico.Connect.Sdk.It.MultiLineHeaderTest" runstate="Runnable" testcasecount="1" result="Failed" site="Child" start-time="2016-09-07 09:51:19Z" end-time="2016-09-07 09:51:19Z" duration="0.003300" total="1" passed="0" failed="1" inconclusive="0" skipped="0" asserts="0">
                <failure>
                  <message><![CDATA[One or more child tests had errors]]></message>
                </failure>
                <test-case id="0-1012" name="Test()" fullname="Ingenico.Connect.Sdk.It.MultiLineHeaderTest.Test()" methodname="Test" classname="Ingenico.Connect.Sdk.It.MultiLineHeaderTest" runstate="Runnable" seed="1605707581" result="Failed" label="Error" start-time="2016-09-07 09:51:19Z" end-time="2016-09-07 09:51:19Z" duration="0.001102" asserts="0">
                  <failure>
                    <message><![CDATA[System.InvalidOperationException : Environment variables connect.api.apiKeyId and connect.api.secretApiKey must be set]]></message>
                    <stack-trace><![CDATA[  at Ingenico.Connect.Sdk.It.IntegrationTest.GetCommunicatorConfiguration () <0x420a8fa0 + 0x00063> in <filename unknown>:0 
  at Ingenico.Connect.Sdk.It.MultiLineHeaderTest+<Test>c__async0.MoveNext () <0x420c4900 + 0x00093> in <filename unknown>:0 
--- End of stack trace from previous location where exception was thrown ---
  at System.Runtime.ExceptionServices.ExceptionDispatchInfo.Throw () <0x420af8e0 + 0x00033> in <filename unknown>:0 
  at NUnit.Framework.Internal.ExceptionHelper.Rethrow (System.Exception exception) <0x420af8b0 + 0x00027> in <filename unknown>:0 
  at NUnit.Framework.Internal.AsyncInvocationRegion+AsyncTaskInvocationRegion.WaitForPendingOperationsToComplete (System.Object invocationResult) <0x420ac080 + 0x000c3> in <filename unknown>:0 
  at NUnit.Framework.Internal.Commands.TestMethodCommand.RunAsyncTestMethod (NUnit.Framework.Internal.TestExecutionContext context) <0x420a7670 + 0x000b0> in <filename unknown>:0 ]]></stack-trace>
                  </failure>
                </test-case>
              </test-suite>
            </test-suite>
            <test-suite type="TestFixture" id="0-1016" name="PaymentProductsGroupsTest" fullname="Ingenico.Connect.Sdk.It.PaymentProductsGroupsTest" classname="Ingenico.Connect.Sdk.It.PaymentProductsGroupsTest" runstate="Runnable" testcasecount="1" result="Failed" site="Child" start-time="2016-09-07 09:51:19Z" end-time="2016-09-07 09:51:19Z" duration="0.005430" total="1" passed="0" failed="1" inconclusive="0" skipped="0" asserts="0">
              <failure>
                <message><![CDATA[One or more child tests had errors]]></message>
              </failure>
              <test-suite type="ParameterizedMethod" id="0-1018" name="Test" fullname="Ingenico.Connect.Sdk.It.PaymentProductsGroupsTest.Test" classname="Ingenico.Connect.Sdk.It.PaymentProductsGroupsTest" runstate="Runnable" testcasecount="1" result="Failed" site="Child" start-time="2016-09-07 09:51:19Z" end-time="2016-09-07 09:51:19Z" duration="0.003224" total="1" passed="0" failed="1" inconclusive="0" skipped="0" asserts="0">
                <failure>
                  <message><![CDATA[One or more child tests had errors]]></message>
                </failure>
                <test-case id="0-1017" name="Test()" fullname="Ingenico.Connect.Sdk.It.PaymentProductsGroupsTest.Test()" methodname="Test" classname="Ingenico.Connect.Sdk.It.PaymentProductsGroupsTest" runstate="Runnable" seed="266292426" result="Failed" label="Error" start-time="2016-09-07 09:51:19Z" end-time="2016-09-07 09:51:19Z" duration="0.001051" asserts="0">
                  <failure>
                    <message><![CDATA[System.InvalidOperationException : Environment variables connect.api.apiKeyId and connect.api.secretApiKey must be set]]></message>
                    <stack-trace><![CDATA[  at Ingenico.Connect.Sdk.It.IntegrationTest.GetClient () <0x420c0cd0 + 0x0007f> in <filename unknown>:0 
  at Ingenico.Connect.Sdk.It.PaymentProductsGroupsTest+<Test>c__async0.MoveNext () <0x420c5480 + 0x001a3> in <filename unknown>:0 
--- End of stack trace from previous location where exception was thrown ---
  at System.Runtime.ExceptionServices.ExceptionDispatchInfo.Throw () <0x420af8e0 + 0x00033> in <filename unknown>:0 
  at NUnit.Framework.Internal.ExceptionHelper.Rethrow (System.Exception exception) <0x420af8b0 + 0x00027> in <filename unknown>:0 
  at NUnit.Framework.Internal.AsyncInvocationRegion+AsyncTaskInvocationRegion.WaitForPendingOperationsToComplete (System.Object invocationResult) <0x420ac080 + 0x000c3> in <filename unknown>:0 
  at NUnit.Framework.Internal.Commands.TestMethodCommand.RunAsyncTestMethod (NUnit.Framework.Internal.TestExecutionContext context) <0x420a7670 + 0x000b0> in <filename unknown>:0 ]]></stack-trace>
                  </failure>
                </test-case>
              </test-suite>
            </test-suite>
            <test-suite type="TestFixture" id="0-1019" name="PaymentProductsTest" fullname="Ingenico.Connect.Sdk.It.PaymentProductsTest" classname="Ingenico.Connect.Sdk.It.PaymentProductsTest" runstate="Runnable" testcasecount="1" result="Failed" site="Child" start-time="2016-09-07 09:51:19Z" end-time="2016-09-07 09:51:19Z" duration="0.005307" total="1" passed="0" failed="1" inconclusive="0" skipped="0" asserts="0">
              <failure>
                <message><![CDATA[One or more child tests had errors]]></message>
              </failure>
              <test-suite type="ParameterizedMethod" id="0-1021" name="Test" fullname="Ingenico.Connect.Sdk.It.PaymentProductsTest.Test" classname="Ingenico.Connect.Sdk.It.PaymentProductsTest" runstate="Runnable" testcasecount="1" result="Failed" site="Child" start-time="2016-09-07 09:51:19Z" end-time="2016-09-07 09:51:19Z" duration="0.003110" total="1" passed="0" failed="1" inconclusive="0" skipped="0" asserts="0">
                <failure>
                  <message><![CDATA[One or more child tests had errors]]></message>
                </failure>
                <test-case id="0-1020" name="Test()" fullname="Ingenico.Connect.Sdk.It.PaymentProductsTest.Test()" methodname="Test" classname="Ingenico.Connect.Sdk.It.PaymentProductsTest" runstate="Runnable" seed="1215850938" result="Failed" label="Error" start-time="2016-09-07 09:51:19Z" end-time="2016-09-07 09:51:19Z" duration="0.000879" asserts="0">
                  <failure>
                    <message><![CDATA[System.InvalidOperationException : Environment variables connect.api.apiKeyId and connect.api.secretApiKey must be set]]></message>
                    <stack-trace><![CDATA[  at Ingenico.Connect.Sdk.It.IntegrationTest.GetClient () <0x420c0cd0 + 0x0007f> in <filename unknown>:0 
  at Ingenico.Connect.Sdk.It.PaymentProductsTest+<Test>c__async0.MoveNext () <0x420c5e60 + 0x0019f> in <filename unknown>:0 
--- End of stack trace from previous location where exception was thrown ---
  at System.Runtime.ExceptionServices.ExceptionDispatchInfo.Throw () <0x420af8e0 + 0x00033> in <filename unknown>:0 
  at NUnit.Framework.Internal.ExceptionHelper.Rethrow (System.Exception exception) <0x420af8b0 + 0x00027> in <filename unknown>:0 
  at NUnit.Framework.Internal.AsyncInvocationRegion+AsyncTaskInvocationRegion.WaitForPendingOperationsToComplete (System.Object invocationResult) <0x420ac080 + 0x000c3> in <filename unknown>:0 
  at NUnit.Framework.Internal.Commands.TestMethodCommand.RunAsyncTestMethod (NUnit.Framework.Internal.TestExecutionContext context) <0x420a7670 + 0x000b0> in <filename unknown>:0 ]]></stack-trace>
                  </failure>
                </test-case>
              </test-suite>
            </test-suite>
            <test-suite type="TestFixture" id="0-1022" name="RiskAssessmentsTest" fullname="Ingenico.Connect.Sdk.It.RiskAssessmentsTest" classname="Ingenico.Connect.Sdk.It.RiskAssessmentsTest" runstate="Runnable" testcasecount="1" result="Failed" site="Child" start-time="2016-09-07 09:51:19Z" end-time="2016-09-07 09:51:19Z" duration="0.005574" total="1" passed="0" failed="1" inconclusive="0" skipped="0" asserts="0">
              <failure>
                <message><![CDATA[One or more child tests had errors]]></message>
              </failure>
              <test-suite type="ParameterizedMethod" id="0-1024" name="Test" fullname="Ingenico.Connect.Sdk.It.RiskAssessmentsTest.Test" classname="Ingenico.Connect.Sdk.It.RiskAssessmentsTest" runstate="Runnable" testcasecount="1" result="Failed" site="Child" start-time="2016-09-07 09:51:19Z" end-time="2016-09-07 09:51:19Z" duration="0.003387" total="1" passed="0" failed="1" inconclusive="0" skipped="0" asserts="0">
                <failure>
                  <message><![CDATA[One or more child tests had errors]]></message>
                </failure>
                <test-case id="0-1023" name="Test()" fullname="Ingenico.Connect.Sdk.It.RiskAssessmentsTest.Test()" methodname="Test" classname="Ingenico.Connect.Sdk.It.RiskAssessmentsTest" runstate="Runnable" seed="178749448" result="Failed" label="Error" start-time="2016-09-07 09:51:19Z" end-time="2016-09-07 09:51:19Z" duration="0.001250" asserts="0">
                  <failure>
                    <message><![CDATA[System.InvalidOperationException : Environment variables connect.api.apiKeyId and connect.api.secretApiKey must be set]]></message>
                    <stack-trace><![CDATA[  at Ingenico.Connect.Sdk.It.IntegrationTest.GetClient () <0x420c0cd0 + 0x0007f> in <filename unknown>:0 
  at Ingenico.Connect.Sdk.It.RiskAssessmentsTest+<Test>c__async0.MoveNext () <0x420c6700 + 0x00677> in <filename unknown>:0 
--- End of stack trace from previous location where exception was thrown ---
  at System.Runtime.ExceptionServices.ExceptionDispatchInfo.Throw () <0x420af8e0 + 0x00033> in <filename unknown>:0 
  at NUnit.Framework.Internal.ExceptionHelper.Rethrow (System.Exception exception) <0x420af8b0 + 0x00027> in <filename unknown>:0 
  at NUnit.Framework.Internal.AsyncInvocationRegion+AsyncTaskInvocationRegion.WaitForPendingOperationsToComplete (System.Object invocationResult) <0x420ac080 + 0x000c3> in <filename unknown>:0 
  at NUnit.Framework.Internal.Commands.TestMethodCommand.RunAsyncTestMethod (NUnit.Framework.Internal.TestExecutionContext context) <0x420a7670 + 0x000b0> in <filename unknown>:0 ]]></stack-trace>
                  </failure>
                </test-case>
              </test-suite>
            </test-suite>
            <test-suite type="TestFixture" id="0-1025" name="SystemProxyTest" fullname="Ingenico.Connect.Sdk.It.SystemProxyTest" classname="Ingenico.Connect.Sdk.It.SystemProxyTest" runstate="Runnable" testcasecount="1" result="Failed" site="Child" start-time="2016-09-07 09:51:19Z" end-time="2016-09-07 09:51:19Z" duration="0.005255" total="1" passed="0" failed="1" inconclusive="0" skipped="0" asserts="0">
              <failure>
                <message><![CDATA[One or more child tests had errors]]></message>
              </failure>
              <test-suite type="ParameterizedMethod" id="0-1027" name="Test" fullname="Ingenico.Connect.Sdk.It.SystemProxyTest.Test" classname="Ingenico.Connect.Sdk.It.SystemProxyTest" runstate="Runnable" testcasecount="1" result="Failed" site="Child" start-time="2016-09-07 09:51:19Z" end-time="2016-09-07 09:51:19Z" duration="0.002939" total="1" passed="0" failed="1" inconclusive="0" skipped="0" asserts="0">
                <failure>
                  <message><![CDATA[One or more child tests had errors]]></message>
                </failure>
                <test-case id="0-1026" name="Test()" fullname="Ingenico.Connect.Sdk.It.SystemProxyTest.Test()" methodname="Test" classname="Ingenico.Connect.Sdk.It.SystemProxyTest" runstate="Runnable" seed="620163158" result="Failed" label="Error" start-time="2016-09-07 09:51:19Z" end-time="2016-09-07 09:51:19Z" duration="0.000777" asserts="0">
                  <failure>
                    <message><![CDATA[System.InvalidOperationException : Environment variables connect.api.apiKeyId and connect.api.secretApiKey must be set]]></message>
                    <stack-trace><![CDATA[  at Ingenico.Connect.Sdk.It.IntegrationTest.GetCommunicatorConfiguration () <0x420a8fa0 + 0x00063> in <filename unknown>:0 
  at Ingenico.Connect.Sdk.It.SystemProxyTest+<Test>c__async0.MoveNext () <0x420c7650 + 0x001ff> in <filename unknown>:0 
--- End of stack trace from previous location where exception was thrown ---
  at System.Runtime.ExceptionServices.ExceptionDispatchInfo.Throw () <0x420af8e0 + 0x00033> in <filename unknown>:0 
  at NUnit.Framework.Internal.ExceptionHelper.Rethrow (System.Exception exception) <0x420af8b0 + 0x00027> in <filename unknown>:0 
  at NUnit.Framework.Internal.AsyncInvocationRegion+AsyncTaskInvocationRegion.WaitForPendingOperationsToComplete (System.Object invocationResult) <0x420ac080 + 0x000c3> in <filename unknown>:0 
  at NUnit.Framework.Internal.Commands.TestMethodCommand.RunAsyncTestMethod (NUnit.Framework.Internal.TestExecutionContext context) <0x420a7670 + 0x000b0> in <filename unknown>:0 ]]></stack-trace>
                  </failure>
                </test-case>
              </test-suite>
            </test-suite>
            <test-suite type="TestFixture" id="0-1028" name="TokenTest" fullname="Ingenico.Connect.Sdk.It.TokenTest" classname="Ingenico.Connect.Sdk.It.TokenTest" runstate="Runnable" testcasecount="1" result="Failed" site="Child" start-time="2016-09-07 09:51:19Z" end-time="2016-09-07 09:51:19Z" duration="0.005761" total="1" passed="0" failed="1" inconclusive="0" skipped="0" asserts="0">
              <failure>
                <message><![CDATA[One or more child tests had errors]]></message>
              </failure>
              <test-suite type="ParameterizedMethod" id="0-1030" name="Test" fullname="Ingenico.Connect.Sdk.It.TokenTest.Test" classname="Ingenico.Connect.Sdk.It.TokenTest" runstate="Runnable" testcasecount="1" result="Failed" site="Child" start-time="2016-09-07 09:51:19Z" end-time="2016-09-07 09:51:19Z" duration="0.003493" total="1" passed="0" failed="1" inconclusive="0" skipped="0" asserts="0">
                <failure>
                  <message><![CDATA[One or more child tests had errors]]></message>
                </failure>
                <test-case id="0-1029" name="Test()" fullname="Ingenico.Connect.Sdk.It.TokenTest.Test()" methodname="Test" classname="Ingenico.Connect.Sdk.It.TokenTest" runstate="Runnable" seed="1420307563" result="Failed" label="Error" start-time="2016-09-07 09:51:19Z" end-time="2016-09-07 09:51:19Z" duration="0.001295" asserts="0">
                  <failure>
                    <message><![CDATA[System.InvalidOperationException : Environment variables connect.api.apiKeyId and connect.api.secretApiKey must be set]]></message>
                    <stack-trace><![CDATA[  at Ingenico.Connect.Sdk.It.IntegrationTest.GetClient () <0x420c0cd0 + 0x0007f> in <filename unknown>:0 
  at Ingenico.Connect.Sdk.It.TokenTest+<Test>c__async0.MoveNext () <0x420c7fb0 + 0x00757> in <filename unknown>:0 
--- End of stack trace from previous location where exception was thrown ---
  at System.Runtime.ExceptionServices.ExceptionDispatchInfo.Throw () <0x420af8e0 + 0x00033> in <filename unknown>:0 
  at NUnit.Framework.Internal.ExceptionHelper.Rethrow (System.Exception exception) <0x420af8b0 + 0x00027> in <filename unknown>:0 
  at NUnit.Framework.Internal.AsyncInvocationRegion+AsyncTaskInvocationRegion.WaitForPendingOperationsToComplete (System.Object invocationResult) <0x420ac080 + 0x000c3> in <filename unknown>:0 
  at NUnit.Framework.Internal.Commands.TestMethodCommand.RunAsyncTestMethod (NUnit.Framework.Internal.TestExecutionContext context) <0x420a7670 + 0x000b0> in <filename unknown>:0 ]]></stack-trace>
                  </failure>
                </test-case>
              </test-suite>
            </test-suite>
          </test-suite>
        </test-suite>
      </test-suite>
    </test-suite>
  </test-suite>
</test-run>